<?xml version="1.0" encoding="utf-8"?>
<!-- This URDF was automatically created by SolidWorks to URDF Exporter! Originally created by Stephen Brawner (brawner@gmail.com) 
     Commit Version: 1.6.0-4-g7f85cfe  Build Version: 1.6.7995.38578
     For more information, please see http://wiki.ros.org/sw_urdf_exporter -->
<robot
  name="dof6arm">

  <link name="world_rviz"/>

  <link
    name="base_link">
    <inertial>
      <origin
        xyz="-4.0864E-17 5.9406E-17 0.039627"
        rpy="0 0 0" />
      <mass
        value="5.5104" />
      <inertia
        ixx="0.032533"
        ixy="-5.673E-17"
        ixz="6.6064E-18"
        iyy="0.032533"
        iyz="2.006E-18"
        izz="0.058905" />
    </inertial>
    <visual>
      <origin
        xyz="0 0 0"
        rpy="0 0 0" />
      <geometry>
        <mesh
          filename="package://dof6arm/meshes/base_link.STL" />
      </geometry>
      <material
        name="">
        <color
          rgba="0.058824 0.058824 0.058824 1" />
      </material>
    </visual>
    <collision>
      <origin
        xyz="0 0 0"
        rpy="0 0 0" />
      <geometry>
        <mesh
          filename="package://dof6arm/meshes/base_link.STL" />
      </geometry>
    </collision>
  </link>

  <joint name="world_joint" type="fixed">
    <parent link="world_rviz"/>
    <child link="base_link"/>
    <origin xyz="0 0 0" rpy="0 0 -1.5708"/>
  </joint>


  <link
    name="link1">
    <inertial>
      <origin
        xyz="0.0563146133187169 0.00239652717597299 0.0813964976165743"
        rpy="0 0 0" />
      <mass
        value="2.25493378297323" />
      <inertia
        ixx="0.011607639577804"
        ixy="-0.000401687438060295"
        ixz="-0.00887971625811838"
        iyy="0.0231563698921059"
        iyz="-0.000351050031071559"
        izz="0.0158798775719755" />
    </inertial>
    <visual>
      <origin
        xyz="0 0 0"
        rpy="0 0 0" />
      <geometry>
        <mesh
          filename="package://dof6arm/meshes/link1.STL" />
      </geometry>
      <material
        name="">
        <color
          rgba="0.898039215686275 0.917647058823529 0.929411764705882 1" />
      </material>
    </visual>
    <collision>
      <origin
        xyz="0 0 0"
        rpy="0 0 0" />
      <geometry>
        <mesh
          filename="package://dof6arm/meshes/link1.STL" />
      </geometry>
    </collision>
  </link>
  <joint
    name="joint1"
    type="revolute">
    <origin
      xyz="0 0 0.085"
      rpy="0 0 1.5708" />
    <parent
      link="base_link" />
    <child
      link="link1" />
    <axis
      xyz="0 0 1" />
    <limit
      lower="-3.14"
      upper="3.14"
      effort="200"
      velocity="10" />
  </joint>
  <link
    name="link2">
    <inertial>
      <origin
        xyz="-0.00806034777883224 0.142663588040641 0.015222810563985"
        rpy="0 0 0" />
      <mass
        value="0.920714229759599" />
      <inertia
        ixx="0.0178612448022285"
        ixy="0.00015240648671748"
        ixz="-3.03747804024019E-05"
        iyy="0.000614865169369136"
        iyz="7.16300104564684E-05"
        izz="0.0182052343067563" />
    </inertial>
    <visual>
      <origin
        xyz="0 0 0"
        rpy="0 0 0" />
      <geometry>
        <mesh
          filename="package://dof6arm/meshes/link2.STL" />
      </geometry>
      <material
        name="">
        <color
          rgba="0.63921568627451 0.666666666666667 0.67843137254902 1" />
      </material>
    </visual>
    <collision>
      <origin
        xyz="0 0 0"
        rpy="0 0 0" />
      <geometry>
        <mesh
          filename="package://dof6arm/meshes/link2.STL" />
      </geometry>
    </collision>
  </link>
  <joint
    name="joint2"
    type="revolute">
    <origin
      xyz="0.15 -0.02 0.16"
      rpy="1.5708 0 0" />
    <parent
      link="link1" />
    <child
      link="link2" />
    <axis
      xyz="0 0 1" />
    <limit
      lower="-1.57"
      upper="1.57"
      effort="200"
      velocity="10" />
  </joint>
  <link
    name="link3">
    <inertial>
      <origin
        xyz="-0.0399152602038644 -0.0446167070292327 -0.0460373494010405"
        rpy="0 0 0" />
      <mass
        value="1.43145554418529" />
      <inertia
        ixx="0.00807676591024907"
        ixy="-0.000324747907195901"
        ixz="-0.000112859910370775"
        iyy="0.00186636959248532"
        iyz="-9.341394228171E-05"
        izz="0.00844554620214213" />
    </inertial>
    <visual>
      <origin
        xyz="0 0 0"
        rpy="0 0 0" />
      <geometry>
        <mesh
          filename="package://dof6arm/meshes/link3.STL" />
      </geometry>
      <material
        name="">
        <color
          rgba="0.898039215686275 0.917647058823529 0.929411764705882 1" />
      </material>
    </visual>
    <collision>
      <origin
        xyz="0 0 0"
        rpy="0 0 0" />
      <geometry>
        <mesh
          filename="package://dof6arm/meshes/link3.STL" />
      </geometry>
    </collision>
  </link>
  <joint
    name="joint3"
    type="revolute">
    <origin
      xyz="0 0.35 0"
      rpy="0 0 1.5708" />
    <parent
      link="link2" />
    <child
      link="link3" />
    <axis
      xyz="0 0 1" />
    <limit
      lower="-3.14"
      upper="1.57"
      effort="200"
      velocity="10" />
  </joint>
  <link
    name="link4">
    <inertial>
      <origin
        xyz="0 -9.99200722162641E-16 0.065964889335451"
        rpy="0 0 0" />
      <mass
        value="0.581435273248315" />
      <inertia
        ixx="0.00158017066215487"
        ixy="2.44381629558985E-10"
        ixz="-7.35582035514334E-19"
        iyy="0.0014063460239573"
        iyz="-1.03875614714129E-18"
        izz="0.000596523986913166" />
    </inertial>
    <visual>
      <origin
        xyz="0 0 0"
        rpy="0 0 0" />
      <geometry>
        <mesh
          filename="package://dof6arm/meshes/link4.STL" />
      </geometry>
      <material
        name="">
        <color
          rgba="0.792156862745098 0.819607843137255 0.933333333333333 1" />
      </material>
    </visual>
    <collision>
      <origin
        xyz="0 0 0"
        rpy="0 0 0" />
      <geometry>
        <mesh
          filename="package://dof6arm/meshes/link4.STL" />
      </geometry>
    </collision>
  </link>
  <joint
    name="joint4"
    type="revolute">
    <origin
      xyz="-0.045 -0.251 -0.0475"
      rpy="1.5708 0 0" />
    <parent
      link="link3" />
    <child
      link="link4" />
    <axis
      xyz="0 0 1" />
    <limit
      lower="-3.14"
      upper="3.14"
      effort="200"
      velocity="10" />
  </joint>
  <link
    name="link5">
    <inertial>
      <origin
        xyz="-1.11022302462516E-16 -0.0589618551287788 0.00017831823908418"
        rpy="0 0 0" />
      <mass
        value="0.339144547925522" />
      <inertia
        ixx="0.000355541202477726"
        ixy="-7.6745270608399E-22"
        ixz="-3.2011026778204E-23"
        iyy="0.000248853470602005"
        iyz="-3.56575702010573E-06"
        izz="0.000358769992191287" />
    </inertial>
    <visual>
      <origin
        xyz="0 0 0"
        rpy="0 0 0" />
      <geometry>
        <mesh
          filename="package://dof6arm/meshes/link5.STL" />
      </geometry>
      <material
        name="">
        <color
          rgba="0.898039215686275 0.917647058823529 0.929411764705882 1" />
      </material>
    </visual>
    <collision>
      <origin
        xyz="0 0 0"
        rpy="0 0 0" />
      <geometry>
        <mesh
          filename="package://dof6arm/meshes/link5.STL" />
      </geometry>
    </collision>
  </link>
  <joint
    name="joint5"
    type="revolute">
    <origin
      xyz="0 0.0005 0.11"
      rpy="-1.5708 0 0" />
    <parent
      link="link4" />
    <child
      link="link5" />
    <axis
      xyz="0 0 1" />
    <limit
      lower="-1.57"
      upper="1.57"
      effort="200"
      velocity="10" />
  </joint>
  <link
    name="link6">
    <inertial>
      <origin
        xyz="0 -1.17961196366423E-15 0.00628470620704225"
        rpy="0 0 0" />
      <mass
        value="0.0762574810565132" />
      <inertia
        ixx="3.79559798700621E-05"
        ixy="-5.78032232262219E-21"
        ixz="5.98732041747797E-22"
        iyy="3.20288004196063E-05"
        iyz="2.81145560238281E-20"
        izz="3.99525744954328E-05" />
    </inertial>
    <visual>
      <origin
        xyz="0 0 0"
        rpy="0 0 0" />
      <geometry>
        <mesh
          filename="package://dof6arm/meshes/link6.STL" />
      </geometry>
      <material
        name="">
        <color
          rgba="0.898039215686275 0.917647058823529 0.929411764705882 1" />
      </material>
    </visual>
    <collision>
      <origin
        xyz="0 0 0"
        rpy="0 0 0" />
      <geometry>
        <mesh
          filename="package://dof6arm/meshes/link6.STL" />
      </geometry>
    </collision>
  </link>
  <joint
    name="joint6"
    type="revolute">
    <origin
      xyz="0 -0.104 0"
      rpy="1.5708 0 0" />
    <parent
      link="link5" />
    <child
      link="link6" />
    <axis
      xyz="0 0 1" />
    <limit
      lower="-3.14"
      upper="3.14"
      effort="200"
      velocity="10" />
  </joint>
  <link
    name="endfector">
    <inertial>
      <origin
        xyz="1.11022302462516E-16 -1.12410081243297E-15 -0.0393199974870748"
        rpy="0 0 0" />
      <mass
        value="0.0762574810565132" />
      <inertia
        ixx="3.79559798700621E-05"
        ixy="-3.43785535520926E-21"
        ixz="1.43016355725182E-22"
        iyy="3.20288004196063E-05"
        iyz="4.99890516382123E-21"
        izz="3.99525744954328E-05" />
    </inertial>
    <visual>
      <origin
        xyz="0 0 0"
        rpy="0 0 0" />
      <geometry>
        <mesh
          filename="package://dof6arm/meshes/endfector.STL" />
      </geometry>
      <material
        name="">
        <color
          rgba="0.898039215686275 0.917647058823529 0.929411764705882 1" />
      </material>
    </visual>
    <collision>
      <origin
        xyz="0 0 0"
        rpy="0 0 0" />
      <geometry>
        <mesh
          filename="package://dof6arm/meshes/endfector.STL" />
      </geometry>
    </collision>
  </link>
  <joint
    name="joint7"
    type="fixed">
    <origin
      xyz="0 0 0.045605"
      rpy="0 0 0" />
    <parent
      link="link6" />
    <child
      link="endfector" />
    <axis
      xyz="0 0 0" />
  </joint>
</robot>