<?xml version="1.0" encoding="utf-8"?>
<!-- This URDF was automatically created by SolidWorks to URDF Exporter! Originally created by Stephen Brawner (brawner@gmail.com) 
     Commit Version: 1.6.0-4-g7f85cfe  Build Version: 1.6.7995.38578
     For more information, please see http://wiki.ros.org/sw_urdf_exporter -->
<robot
  name="dof6arm">
  <link
    name="base_link">
    <inertial>
      <origin
        xyz="-4.0770194671452E-17 5.83561963043712E-17 0.0396270399100885"
        rpy="0 0 0" />
      <mass
        value="5.51043299491621" />
      <inertia
        ixx="0.0325325116702204"
        ixy="-5.66701954647961E-17"
        ixz="6.57943646357064E-18"
        iyy="0.0325325116702204"
        iyz="1.85395737247361E-18"
        izz="0.0589048225198257" />
    </inertial>
    <visual>
      <origin
        xyz="0 0 0"
        rpy="0 0 0" />
      <geometry>
        <mesh
          filename="package://dof6arm/meshes/base_link.STL" />
      </geometry>
      <material
        name="">
        <color
          rgba="0.0588235294117647 0.0588235294117647 0.0588235294117647 1" />
      </material>
    </visual>
    <collision>
      <origin
        xyz="0 0 0"
        rpy="0 0 0" />
      <geometry>
        <mesh
          filename="package://dof6arm/meshes/base_link.STL" />
      </geometry>
    </collision>
  </link>
  <link
    name="link1">
    <inertial>
      <origin
        xyz="0.0563146133187169 0.00239652717597299 0.0813964976165743"
        rpy="0 0 0" />
      <mass
        value="2.25493378297323" />
      <inertia
        ixx="0.011607639577804"
        ixy="-0.000401687438060295"
        ixz="-0.00887971625811838"
        iyy="0.0231563698921059"
        iyz="-0.000351050031071559"
        izz="0.0158798775719755" />
    </inertial>
    <visual>
      <origin
        xyz="0 0 0"
        rpy="0 0 0" />
      <geometry>
        <mesh
          filename="package://dof6arm/meshes/link1.STL" />
      </geometry>
      <material
        name="">
        <color
          rgba="0.898039215686275 0.917647058823529 0.929411764705882 1" />
      </material>
    </visual>
    <collision>
      <origin
        xyz="0 0 0"
        rpy="0 0 0" />
      <geometry>
        <mesh
          filename="package://dof6arm/meshes/link1.STL" />
      </geometry>
    </collision>
  </link>
  <joint
    name="joint0"
    type="continuous">
    <origin
      xyz="0 0 0.085"
      rpy="0 0 1.57079632679489" />
    <parent
      link="base_link" />
    <child
      link="link1" />
    <axis
      xyz="0 0 1" />
    <limit
      lower="0"
      upper="6.28"
      effort="200"
      velocity="10" />
  </joint>
  <link
    name="link2">
    <inertial>
      <origin
        xyz="-0.00806034777883222 0.142663588040641 0.015222810563985"
        rpy="0 0 0" />
      <mass
        value="0.920714229759599" />
      <inertia
        ixx="0.0178612448022285"
        ixy="0.00015240648671748"
        ixz="-3.03747804024019E-05"
        iyy="0.000614865169369136"
        iyz="7.16300104564684E-05"
        izz="0.0182052343067563" />
    </inertial>
    <visual>
      <origin
        xyz="0 0 0"
        rpy="0 0 0" />
      <geometry>
        <mesh
          filename="package://dof6arm/meshes/link2.STL" />
      </geometry>
      <material
        name="">
        <color
          rgba="0.63921568627451 0.666666666666667 0.67843137254902 1" />
      </material>
    </visual>
    <collision>
      <origin
        xyz="0 0 0"
        rpy="0 0 0" />
      <geometry>
        <mesh
          filename="package://dof6arm/meshes/link2.STL" />
      </geometry>
    </collision>
  </link>
  <joint
    name="joint1"
    type="continuous">
    <origin
      xyz="0.150000000000022 -0.019999999999832 0.159999999999999"
      rpy="1.5707963267949 0 0" />
    <parent
      link="link1" />
    <child
      link="link2" />
    <axis
      xyz="0 0 1" />
    <limit
      lower="-0.70"
      upper="0.70"
      effort="200"
      velocity="10" />
  </joint>
  <link
    name="link3">
    <inertial>
      <origin
        xyz="-0.0399152602038644 -0.0446167070292327 -0.0460373494010405"
        rpy="0 0 0" />
      <mass
        value="1.43145554418529" />
      <inertia
        ixx="0.0080767659102491"
        ixy="-0.000324747907195899"
        ixz="-0.000112859910370775"
        iyy="0.00186636959248532"
        iyz="-9.34139422817104E-05"
        izz="0.00844554620214216" />
    </inertial>
    <visual>
      <origin
        xyz="0 0 0"
        rpy="0 0 0" />
      <geometry>
        <mesh
          filename="package://dof6arm/meshes/link3.STL" />
      </geometry>
      <material
        name="">
        <color
          rgba="0.898039215686275 0.917647058823529 0.929411764705882 1" />
      </material>
    </visual>
    <collision>
      <origin
        xyz="0 0 0"
        rpy="0 0 0" />
      <geometry>
        <mesh
          filename="package://dof6arm/meshes/link3.STL" />
      </geometry>
    </collision>
  </link>
  <joint
    name="joint2"
    type="continuous">
    <origin
      xyz="0 0.350000000000001 0"
      rpy="0 0 1.5707963267949" />
    <parent
      link="link2" />
    <child
      link="link3" />
    <axis
      xyz="0 0 1" />
    <limit
      lower="-4.71"
      upper="1.57"
      effort="200"
      velocity="10" />
  </joint>
  <link
    name="link4">
    <inertial>
      <origin
        xyz="-1.11022302462516E-16 -1.00613961606655E-15 0.065964889335451"
        rpy="0 0 0" />
      <mass
        value="0.581435273248316" />
      <inertia
        ixx="0.00158017066215487"
        ixy="2.44381629720969E-10"
        ixz="-7.39109767867271E-19"
        iyy="0.0014063460239573"
        iyz="-1.0554814422074E-18"
        izz="0.000596523986913165" />
    </inertial>
    <visual>
      <origin
        xyz="0 0 0"
        rpy="0 0 0" />
      <geometry>
        <mesh
          filename="package://dof6arm/meshes/link4.STL" />
      </geometry>
      <material
        name="">
        <color
          rgba="0.792156862745098 0.819607843137255 0.933333333333333 1" />
      </material>
    </visual>
    <collision>
      <origin
        xyz="0 0 0"
        rpy="0 0 0" />
      <geometry>
        <mesh
          filename="package://dof6arm/meshes/link4.STL" />
      </geometry>
    </collision>
  </link>
  <joint
    name="joint3"
    type="continuous">
    <origin
      xyz="-0.045 -0.251 -0.0474999999999995"
      rpy="1.5707963267949 0 0" />
    <parent
      link="link3" />
    <child
      link="link4" />
    <axis
      xyz="0 0 1" />
    <limit
      lower="-3.14"
      upper="3.14"
      effort="200"
      velocity="10" />
  </joint>
  <link
    name="link5">
    <inertial>
      <origin
        xyz="0 -0.0589618551287789 0.00017831823908418"
        rpy="0 0 0" />
      <mass
        value="0.339144547925522" />
      <inertia
        ixx="0.000355541202477726"
        ixy="-2.59477164725886E-22"
        ixz="1.64281985827674E-22"
        iyy="0.000248853470602005"
        iyz="-3.56575702010573E-06"
        izz="0.000358769992191287" />
    </inertial>
    <visual>
      <origin
        xyz="0 0 0"
        rpy="0 0 0" />
      <geometry>
        <mesh
          filename="package://dof6arm/meshes/link5.STL" />
      </geometry>
      <material
        name="">
        <color
          rgba="0.898039215686275 0.917647058823529 0.929411764705882 1" />
      </material>
    </visual>
    <collision>
      <origin
        xyz="0 0 0"
        rpy="0 0 0" />
      <geometry>
        <mesh
          filename="package://dof6arm/meshes/link5.STL" />
      </geometry>
    </collision>
  </link>
  <joint
    name="joint4"
    type="continuous">
    <origin
      xyz="0 0.00050000000000075 0.11"
      rpy="-1.5707963267949 0 0" />
    <parent
      link="link4" />
    <child
      link="link5" />
    <axis
      xyz="0 0 1" />
    <limit
      lower="-1.57"
      upper="1.57"
      effort="200"
      velocity="10" />
  </joint>
  <link
    name="link6">
    <inertial>
      <origin
        xyz="1.11022302462516E-16 -1.17961196366423E-15 0.00628470620704225"
        rpy="0 0 0" />
      <mass
        value="0.0762574810565132" />
      <inertia
        ixx="3.79559798700621E-05"
        ixy="-5.78143732477703E-21"
        ixz="3.82889549930142E-22"
        iyy="3.20288004196063E-05"
        iyz="2.64604355316731E-20"
        izz="3.99525744954328E-05" />
    </inertial>
    <visual>
      <origin
        xyz="0 0 0"
        rpy="0 0 0" />
      <geometry>
        <mesh
          filename="package://dof6arm/meshes/link6.STL" />
      </geometry>
      <material
        name="">
        <color
          rgba="0.898039215686275 0.917647058823529 0.929411764705882 1" />
      </material>
    </visual>
    <collision>
      <origin
        xyz="0 0 0"
        rpy="0 0 0" />
      <geometry>
        <mesh
          filename="package://dof6arm/meshes/link6.STL" />
      </geometry>
    </collision>
  </link>
  <joint
    name="joint5"
    type="continuous">
    <origin
      xyz="0 -0.104 0"
      rpy="1.5707963267949 0 0" />
    <parent
      link="link5" />
    <child
      link="link6" />
    <axis
      xyz="0 0 1" />
    <limit
      lower="-3.14"
      upper="3.14"
      effort="200"
      velocity="10" />
  </joint>
  <link
    name="endfector">
    <inertial>
      <origin
        xyz="1.11022302462516E-16 -1.12410081243297E-15 -0.0393199974870748"
        rpy="0 0 0" />
      <mass
        value="0.0762574810565132" />
      <inertia
        ixx="3.79559798700621E-05"
        ixy="-3.42762367535721E-21"
        ixz="4.79566405709865E-23"
        iyy="3.20288004196063E-05"
        iyz="3.36252849364977E-21"
        izz="3.99525744954328E-05" />
    </inertial>
    <visual>
      <origin
        xyz="0 0 0"
        rpy="0 0 0" />
      <geometry>
        <mesh
          filename="package://dof6arm/meshes/endfector.STL" />
      </geometry>
      <material
        name="">
        <color
          rgba="0.898039215686275 0.917647058823529 0.929411764705882 1" />
      </material>
    </visual>
    <collision>
      <origin
        xyz="0 0 0"
        rpy="0 0 0" />
      <geometry>
        <mesh
          filename="package://dof6arm/meshes/endfector.STL" />
      </geometry>
    </collision>
  </link>
  <joint
    name="joint6"
    type="fixed">
    <origin
      xyz="0 0 0.045605"
      rpy="0 0 0" />
    <parent
      link="link6" />
    <child
      link="endfector" />
    <axis
      xyz="0 0 0" />
  </joint>
</robot>